<?xml version="1.0" encoding="UTF-8"?>
<testng-results ignored="1" total="2" passed="0" failed="1" skipped="0">
  <reporter-output>
  </reporter-output>
  <suite started-at="2020-10-31T18:52:27 IST" name="Default suite" finished-at="2020-10-31T18:52:33 IST" duration-ms="6443">
    <groups>
    </groups>
    <test started-at="2020-10-31T18:52:27 IST" name="Default test" finished-at="2020-10-31T18:52:33 IST" duration-ms="6443">
      <class name="azurepipelienpoc.NewTest">
        <test-method signature="urlTest()[pri:0, instance:azurepipelienpoc.NewTest@2e1d27ba]" started-at="2020-10-31T18:52:27 IST" name="urlTest" finished-at="2020-10-31T18:52:33 IST" duration-ms="6373" status="FAIL">
          <exception class="java.lang.AssertionError">
            <message>
              <![CDATA[expected [https://www.abc.com/] but found [https://www.google.com/]]]>
            </message>
            <full-stacktrace>
              <![CDATA[java.lang.AssertionError: expected [https://www.abc.com/] but found [https://www.google.com/]
at org.testng.Assert.fail(Assert.java:99)
at org.testng.Assert.failNotEquals(Assert.java:1037)
at org.testng.Assert.assertEqualsImpl(Assert.java:140)
at org.testng.Assert.assertEquals(Assert.java:122)
at org.testng.Assert.assertEquals(Assert.java:629)
at org.testng.Assert.assertEquals(Assert.java:639)
at azurepipelienpoc.NewTest.urlTest(NewTest.java:11)
at java.base/jdk.internal.reflect.NativeMethodAccessorImpl.invoke0(Native Method)
at java.base/jdk.internal.reflect.NativeMethodAccessorImpl.invoke(NativeMethodAccessorImpl.java:62)
at java.base/jdk.internal.reflect.DelegatingMethodAccessorImpl.invoke(DelegatingMethodAccessorImpl.java:43)
at java.base/java.lang.reflect.Method.invoke(Method.java:564)
at org.testng.internal.MethodInvocationHelper.invokeMethod(MethodInvocationHelper.java:132)
at org.testng.internal.TestInvoker.invokeMethod(TestInvoker.java:599)
at org.testng.internal.TestInvoker.invokeTestMethod(TestInvoker.java:174)
at org.testng.internal.MethodRunner.runInSequence(MethodRunner.java:46)
at org.testng.internal.TestInvoker$MethodInvocationAgent.invoke(TestInvoker.java:822)
at org.testng.internal.TestInvoker.invokeTestMethods(TestInvoker.java:147)
at org.testng.internal.TestMethodWorker.invokeTestMethods(TestMethodWorker.java:146)
at org.testng.internal.TestMethodWorker.run(TestMethodWorker.java:128)
at java.base/java.util.ArrayList.forEach(ArrayList.java:1511)
at org.testng.TestRunner.privateRun(TestRunner.java:764)
at org.testng.TestRunner.run(TestRunner.java:585)
at org.testng.SuiteRunner.runTest(SuiteRunner.java:384)
at org.testng.SuiteRunner.runSequentially(SuiteRunner.java:378)
at org.testng.SuiteRunner.privateRun(SuiteRunner.java:337)
at org.testng.SuiteRunner.run(SuiteRunner.java:286)
at org.testng.SuiteRunnerWorker.runSuite(SuiteRunnerWorker.java:53)
at org.testng.SuiteRunnerWorker.run(SuiteRunnerWorker.java:96)
at org.testng.TestNG.runSuitesSequentially(TestNG.java:1218)
at org.testng.TestNG.runSuitesLocally(TestNG.java:1140)
at org.testng.TestNG.runSuites(TestNG.java:1069)
at org.testng.TestNG.run(TestNG.java:1037)
at org.testng.remote.AbstractRemoteTestNG.run(AbstractRemoteTestNG.java:115)
at org.testng.remote.RemoteTestNG.initAndRun(RemoteTestNG.java:251)
at org.testng.remote.RemoteTestNG.main(RemoteTestNG.java:77)
]]>
            </full-stacktrace>
          </exception> <!-- java.lang.AssertionError -->
          <reporter-output>
          </reporter-output>
        </test-method> <!-- urlTest -->
      </class> <!-- azurepipelienpoc.NewTest -->
    </test> <!-- Default test -->
  </suite> <!-- Default suite -->
</testng-results>
